<?xml version="1.0"?>
<robot name="autobot" xmlns:xacro="http://www.ros.org/wiki/xacro">
  <xacro:include filename="/home/jaden/autobot/install/autobot_description/urdf/autobot.xacro"/>
  <link
    name="base_link">
    <inertial>
      <origin
        xyz="0.0083636 0.00032574 0.012906"
        rpy="0 0 0" />
      <mass
        value="1.7212" />
      <inertia
        ixx="0.0017904"
        ixy="-1.7258E-19"
        ixz="-2.4796E-19"
        iyy="0.0028365"
        iyz="3.1906E-19"
        izz="0.0043783" />
    </inertial>
    <visual>
      <origin
        xyz="0 0 0"
        rpy="0 0 0" />
      <geometry>
        <mesh
          filename="/home/jaden/autobot/install/autobot_gazebo/share/autobot_gazebo/meshes/base_link.STL" />
      </geometry>
      <material
        name="">
        <color
          rgba="0.89804 0.91765 0.92941 1" />
      </material>
    </visual>
    <collision>
      <origin
        xyz="0 0 0"
        rpy="0 0 0" />
      <geometry>
        <mesh
          filename="/home/jaden/autobot/install/autobot_gazebo/share/autobot_gazebo/meshes/base_link.STL" />
      </geometry>
    </collision>
  </link>
  <link
    name="left_back_link">
    <inertial>
      <origin
        xyz="-0.00015314 -0.0025023 6.8342E-05"
        rpy="0 0 0" />
      <mass
        value="0.019493" />
      <inertia
        ixx="5.9732E-06"
        ixy="1.6948E-08"
        ixz="3.0697E-08"
        iyy="1.1909E-05"
        iyz="-7.5634E-09"
        izz="6.0282E-06" />
    </inertial>
    <visual>
      <origin
        xyz="0 0 0"
        rpy="0 0 0" />
      <geometry>
        <mesh
          filename="/home/jaden/autobot/install/autobot_gazebo/share/autobot_gazebo/meshes/left_back_link.STL" />
      </geometry>
      <material
        name="">
        <color
          rgba="0.29804 0.29804 0.29804 1" />
      </material>
    </visual>
    <collision>
      <origin
        xyz="0 0 0"
        rpy="0 0 0" />
      <geometry>
        <mesh
          filename="/home/jaden/autobot/install/autobot_gazebo/share/autobot_gazebo/meshes/left_back_link.STL" />
      </geometry>
    </collision>
  </link>
  <joint
    name="left_back_joint"
    type="continuous">
    <origin
      xyz="-0.11481 0.11014 -0.016954"
      rpy="0 0 0" />
    <parent
      link="base_link" />
    <child
      link="left_back_link" />
    <axis
      xyz="0 1 0" />
    <dynamics
      damping="0.01"
      friction="0.01" />
  </joint>
  <link
    name="right_back_link">
    <inertial>
      <origin
        xyz="0.00016187 0.0025023 4.3839E-05"
        rpy="0 0 0" />
      <mass
        value="0.019493" />
      <inertia
        ixx="5.9651E-06"
        ixy="1.7914E-08"
        ixz="-2.0813E-08"
        iyy="1.1909E-05"
        iyz="4.8516E-09"
        izz="6.0363E-06" />
    </inertial>
    <visual>
      <origin
        xyz="0 0 0"
        rpy="0 0 0" />
      <geometry>
        <mesh
          filename="/home/jaden/autobot/install/autobot_gazebo/share/autobot_gazebo/meshes/right_back_link.STL" />
      </geometry>
      <material
        name="">
        <color
          rgba="0.29804 0.29804 0.29804 1" />
      </material>
    </visual>
    <collision>
      <origin
        xyz="0 0 0"
        rpy="0 0 0" />
      <geometry>
        <mesh
          filename="/home/jaden/autobot/install/autobot_gazebo/share/autobot_gazebo/meshes/right_back_link.STL" />
      </geometry>
    </collision>
  </link>
  <joint
    name="right_back_joint"
    type="continuous">
    <origin
      xyz="-0.11481 -0.11014 -0.016954"
      rpy="0 0 0" />
    <parent
      link="base_link" />
    <child
      link="right_back_link" />
    <axis
      xyz="0 1 0" />
    <dynamics
      damping="0.01"
      friction="0.01" />
  </joint>
  <link
    name="left_front_link">
    <inertial>
      <origin
        xyz="-9.7213E-05 -0.0025023 0.00013665"
        rpy="0 0 0" />
      <mass
        value="0.019493" />
      <inertia
        ixx="6.0142E-06"
        ixy="1.0759E-08"
        ixz="3.8962E-08"
        iyy="1.1909E-05"
        iyz="-1.5123E-08"
        izz="5.9872E-06" />
    </inertial>
    <visual>
      <origin
        xyz="0 0 0"
        rpy="0 0 0" />
      <geometry>
        <mesh
          filename="/home/jaden/autobot/install/autobot_gazebo/share/autobot_gazebo/meshes/left_front_link.STL" />
      </geometry>
      <material
        name="">
        <color
          rgba="0.29804 0.29804 0.29804 1" />
      </material>
    </visual>
    <collision>
      <origin
        xyz="0 0 0"
        rpy="0 0 0" />
      <geometry>
        <mesh
          filename="/home/jaden/autobot/install/autobot_gazebo/share/autobot_gazebo/meshes/left_front_link.STL" />
      </geometry>
    </collision>
  </link>
  <joint
    name="left_front_joint"
    type="continuous">
    <origin
      xyz="0.11481 0.11026 -0.016955"
      rpy="0 0 0" />
    <parent
      link="base_link" />
    <child
      link="left_front_link" />
    <axis
      xyz="0 1 0" />
    <dynamics
      damping="0.01"
      friction="0.01" />
  </joint>
  <link
    name="right_front_link">
    <inertial>
      <origin
        xyz="0.00014263 0.0025023 8.8209E-05"
        rpy="0 0 0" />
      <mass
        value="0.019493" />
      <inertia
        ixx="5.9823E-06"
        ixy="1.5785E-08"
        ixz="-3.69E-08"
        iyy="1.1909E-05"
        iyz="9.7621E-09"
        izz="6.0191E-06" />
    </inertial>
    <visual>
      <origin
        xyz="0 0 0"
        rpy="0 0 0" />
      <geometry>
        <mesh
          filename="/home/jaden/autobot/install/autobot_gazebo/share/autobot_gazebo/meshes/right_front_link.STL" />
      </geometry>
      <material
        name="">
        <color
          rgba="0.29804 0.29804 0.29804 1" />
      </material>
    </visual>
    <collision>
      <origin
        xyz="0 0 0"
        rpy="0 0 0" />
      <geometry>
        <mesh
          filename="/home/jaden/autobot/install/autobot_gazebo/share/autobot_gazebo/meshes/right_front_link.STL" />
      </geometry>
    </collision>
  </link>
  <joint
    name="right_front_joint"
    type="continuous">
    <origin
      xyz="0.11481 -0.11026 -0.016955"
      rpy="0 0 0" />
    <parent
      link="base_link" />
    <child
      link="right_front_link" />
    <axis
      xyz="0 1 0" />
    <dynamics
      damping="0.01"
      friction="0.01" />
  </joint>
  <link
    name="lidar_link">
    <inertial>
      <origin
        xyz="1.249E-16 -6.9389E-17 0"
        rpy="0 0 0" />
      <mass
        value="0.082049" />
      <inertia
        ixx="2.5089E-05"
        ixy="-1.8986E-21"
        ixz="-9.4476E-21"
        iyy="2.5089E-05"
        iyz="9.4278E-21"
        izz="4.1355E-05" />
    </inertial>
    <visual>
      <origin
        xyz="0 0 0"
        rpy="0 0 0" />
      <geometry>
        <mesh
          filename="/home/jaden/autobot/install/autobot_gazebo/share/autobot_gazebo/meshes/lidar_link.STL" />
      </geometry>
      <material
        name="">
        <color
          rgba="1 1 1 1" />
      </material>
    </visual>
    <collision>
      <origin
        xyz="0 0 0"
        rpy="0 0 0" />
      <geometry>
        <mesh
          filename="/home/jaden/autobot/install/autobot_gazebo/share/autobot_gazebo/meshes/lidar_link.STL" />
      </geometry>
    </collision>
  </link>
  <joint
    name="lidar_joint"
    type="fixed">
    <origin
      xyz="0 0 0.11462"
      rpy="0 0 0" />
    <parent
      link="base_link" />
    <child
      link="lidar_link" />
    <axis
      xyz="0 0 0" />
  </joint>
  <gazebo>
      <plugin name="skid_steer_drive_controller" filename="libgazebo_ros_diff_drive.so">
          <!-- Update rate -->
          <update_rate>50</update_rate>
          <!-- Number of wheel pairs -->
          <num_wheel_pairs>2</num_wheel_pairs>
          <!-- wheels0 -->
          <left_joint>left_back_joint</left_joint>
          <right_joint>right_back_joint</right_joint>
          <!-- wheels1-->
          <left_joint>left_front_joint</left_joint>
          <right_joint>right_front_joint</right_joint>
          <!-- kinematics -->
          <wheel_separation>0.21532</wheel_separation>
          <wheel_separation>0.21532</wheel_separation>
          <wheel_diameter>0.06985</wheel_diameter>
          <wheel_diameter>0.06985</wheel_diameter>
          <!-- limits -->
          <max_wheel_torque>20</max_wheel_torque>
          <!-- output -->
          <publish_odom>true</publish_odom>
          <publish_odom_tf>true</publish_odom_tf>
          <publish_wheel_tf>true</publish_wheel_tf>
          <odometry_frame>odom</odometry_frame>
          <robot_base_frame>base_link</robot_base_frame>
          <command_topic>cmd_vel</command_topic>
      </plugin>
  </gazebo>

  <gazebo reference="base_link">
      <material>Gazebo/White</material>
  </gazebo>

  <gazebo reference="left_back_link">
      <material>Gazebo/Grey</material>
  </gazebo>

  <gazebo reference="left_front_link">
      <material>Gazebo/Grey</material>
  </gazebo>

  <gazebo reference="right_back_link">
      <material>Gazebo/Grey</material>
  </gazebo>

  <gazebo reference="right_front_link">
      <material>Gazebo/Grey</material>
  </gazebo>

  <gazebo reference="lidar_link">
      <material>Gazebo/Blue</material>
      <sensor type="gpu_ray" name="head_hokuyo_sensor">
        <pose>0 0 0 0 0 0</pose>
        <visualize>false</visualize>
        <update_rate>40</update_rate>
        <ray>
          <scan>
            <horizontal>
              <samples>720</samples>
              <resolution>1</resolution>
              <min_angle>-3.14</min_angle>
              <max_angle>3.14</max_angle>
            </horizontal>
          </scan>
          <range>
            <min>0.10</min>
            <max>30.0</max>
            <resolution>0.01</resolution>
          </range>
          <noise>
            <type>gaussian</type>
            <mean>0.0</mean>
            <stddev>0.01</stddev>
          </noise>
        </ray>
        <plugin name="gazebo_ros_head_hokuyo_controller" filename="libgazebo_ros_ray_sensor.so">
          <output_type>sensor_msgs/LaserScan</output_type>
          <topic_name>scan</topic_name>
          <frame_name>lidar_link</frame_name>
        </plugin>
      </sensor>
  </gazebo>
</robot>