<?xml version="1.0" ?>
<robot 
  name="autobot" xmlns:xacro="http://ros.org/wiki/xacro" >
  <link
    name="base_link">
    <inertial>
      <origin
        xyz="0.0181995182140738 -3.2612801348364E-16 -0.00276660416271973"
        rpy="0 0 0" />
      <mass
        value="0.5" />
      <inertia
        ixx="0.000696660783343318"
        ixy="-4.10541788338937E-18"
        ixz="-1.73835831247213E-05"
        iyy="0.000483852662901766"
        iyz="-9.39165770832175E-20"
        izz="0.00110580849651397" />
    </inertial>
    <visual>
      <origin
        xyz="0 0 0"
        rpy="0 0 0" />
      <geometry>
        <mesh
          filename="/home/jaden/autobot/install/autobot_gazebo/share/autobot_gazebo/meshes/base_link.dae" />
      </geometry>
      <material
        name="white">
        <color
          rgba="0.898039215686275 0.917647058823529 0.929411764705882 1" />
      </material>
    </visual>
    <collision>
      <origin
        xyz="0 0 0"
        rpy="0 0 0" />
      <geometry>
        <mesh
          filename="/home/jaden/autobot/install/autobot_gazebo/share/autobot_gazebo/meshes/base_link.dae" />
      </geometry>
      <surface>
        <friction>
          <ode>
            <mu>0</mu>
            <mu2>0</mu2>
          </ode>
        </friction>
        <contact>
          <ode>
            <kp>0</kp>
            <kd>0</kd>
          </ode>
        </contact>
      </surface>
    </collision>
  </link>
  <link
    name="left_link">
    <inertial>
      <origin
        xyz="0 -0.00253999999999997 -3.46944695195361E-18"
        rpy="0 0 0" />
      <mass
        value="0.1" />
      <inertia
        ixx="5.95463591243264E-06"
        ixy="-3.93222974369193E-21"
        ixz="1.09725654735065E-22"
        iyy="1.18262560040685E-05"
        iyz="9.79810897308325E-21"
        izz="5.95463591243264E-06" />
    </inertial>
    <visual>
      <origin
        xyz="0 0 0"
        rpy="0 0 0" />
      <geometry>
        <mesh
          filename="/home/jaden/autobot/install/autobot_gazebo/share/autobot_gazebo/meshes/left_link.dae" />
      </geometry>
      <material
        name="white">
        <color
          rgba="0.898039215686275 0.917647058823529 0.929411764705882 1" />
      </material>
    </visual>
    <collision>
      <origin
        xyz="0 0 0"
        rpy="0 0 0" />
      <geometry>
        <mesh
          filename="/home/jaden/autobot/install/autobot_gazebo/share/autobot_gazebo/meshes/left_link.dae" />
      </geometry>
      <surface>
        <friction>
          <ode>
            <mu>1000</mu>
            <mu2>1000</mu2>
          </ode>
        </friction>
      </surface>
    </collision>
  </link>
  <joint
    name="left_joint"
    type="continuous">
    <origin
      xyz="-0.23579 0.11463 -0.018932"
      rpy="0 0 0" />
    <parent
      link="base_link" />
    <child
      link="left_link" />
    <axis
      xyz="0 1 0" />
  </joint>
  <link
    name="right_link">
    <inertial>
      <origin
        xyz="8.32667268468867E-17 0.00254 -3.46944695195361E-17"
        rpy="0 0 0" />
      <mass
        value="0.1" />
      <inertia
        ixx="5.95463591243264E-06"
        ixy="-7.43403341671298E-25"
        ixz="1.94041797160579E-23"
        iyy="1.18262560040684E-05"
        iyz="3.16575996755698E-24"
        izz="5.95463591243264E-06" />
    </inertial>
    <visual>
      <origin
        xyz="0 0 0"
        rpy="0 0 0" />
      <geometry>
        <mesh
          filename="/home/jaden/autobot/install/autobot_gazebo/share/autobot_gazebo/meshes/right_link.dae" />
      </geometry>
      <material
        name="white">
        <color
          rgba="0.898039215686275 0.917647058823529 0.929411764705882 1" />
      </material>
    </visual>
    <collision>
      <origin
        xyz="0 0 0"
        rpy="0 0 0" />
      <geometry>
        <mesh
          filename="/home/jaden/autobot/install/autobot_gazebo/share/autobot_gazebo/meshes/right_link.dae" />
      </geometry>
      <surface>
        <friction>
          <ode>
            <mu>1000</mu>
            <mu2>1000</mu2>
          </ode>
        </friction>
      </surface>
    </collision>
  </link>
  <joint
    name="right_joint"
    type="continuous">
    <origin
      xyz="-0.23579 -0.10577 -0.018932"
      rpy="0 0 0" />
    <parent
      link="base_link" />
    <child
      link="right_link" />
    <axis
      xyz="0 1 0" />
  </joint>
  <link
    name="lidar_link">
    <inertial>
      <origin
        xyz="3.46944695195361E-18 0 2.77555756156289E-17"
        rpy="0 0 0" />
      <mass
        value="0.0804398123067278" />
      <inertia
        ixx="2.45968020156801E-05"
        ixy="-5.37865921506481E-22"
        ixz="-8.89472774442708E-21"
        iyy="2.45968020156801E-05"
        iyz="-7.17154562008641E-22"
        izz="4.05441791467254E-05" />
    </inertial>
    <visual>
      <origin
        xyz="0 0 0"
        rpy="0 0 0" />
      <geometry>
        <mesh
          filename="/home/jaden/autobot/install/autobot_gazebo/share/autobot_gazebo/meshes/lidar_link.dae" />
      </geometry>
      <material
        name="white">
        <color
          rgba="0.898039215686275 0.917647058823529 0.929411764705882 1" />
      </material>
    </visual>
    <collision>
      <origin
        xyz="0 0 0"
        rpy="0 0 0" />
      <geometry>
        <mesh
          filename="/home/jaden/autobot/install/autobot_gazebo/share/autobot_gazebo/meshes/lidar_link.dae" />
      </geometry>
    </collision>
  </link>
  <joint
    name="lidar_joint"
    type="fixed">
    <origin
      xyz="-0.026679 0.0043672 0.11264"
      rpy="0 0 0" />
    <parent
      link="base_link" />
    <child
      link="lidar_link" />
    <axis
      xyz="0 0 0" />
  </joint>
  <link
    name="caster_link">
    <inertial>
      <origin
        xyz="0.00204422266917935 -1.08268748133522E-10 0.0100778968873803"
        rpy="0 0 0" />
      <mass
        value="0.0507696152770883" />
      <inertia
        ixx="2.02368641684853E-05"
        ixy="1.94401887657203E-15"
        ixz="-1.39248597555112E-06"
        iyy="1.16296889446219E-05"
        iyz="2.06811232036619E-14"
        izz="1.7725587785761E-05" />
    </inertial>
    <visual>
      <origin
        xyz="0 0 0"
        rpy="0 0 0" />
      <geometry>
        <mesh
          filename="/home/jaden/autobot/install/autobot_gazebo/share/autobot_gazebo/meshes/caster_link.dae" />
      </geometry>
      <material
        name="white">
        <color
          rgba="0.898039215686275 0.917647058823529 0.929411764705882 1" />
      </material>
    </visual>
    <collision>
      <origin
        xyz="0 0 0"
        rpy="0 0 0" />
      <geometry>
        <mesh
          filename="/home/jaden/autobot/install/autobot_gazebo/share/autobot_gazebo/meshes/caster_link.dae" />
      </geometry>
      <surface>
        <bounce>
          <restitution_coefficient>0</restitution_coefficient>
          <threshold>100000</threshold>
        </bounce>
        <friction>
          <ode>
            <mu>0</mu>
            <mu2>0</mu2>
            <fdir1> 0 0 0</fdir1>
            <slip1>0</slip1>
            <slip2>0</slip2>
          </ode>
        </friction>
        <contact>
          <ode>
            <soft_cfm>0</soft_cfm>
            <soft_erp>0.2</soft_erp>
            <kp>1000000000000</kp>
            <kd>1</kd>
            <max_vel>100</max_vel>
            <min_depth>0.001</min_depth>
          </ode>
        </contact>
      </surface>
    </collision>
  </link>
  <joint
    name="caster_joint"
    type="fixed">
    <origin
      xyz="-0.026679 0.0043672 -0.027377"
      rpy="0 0 0" />
    <parent
      link="base_link" />
    <child
      link="caster_link" />
    <axis
      xyz="0 0 0" />
  </joint>
  <gazebo reference="base_link">
    <material>Gazebo/White</material>
  </gazebo>
  <gazebo reference="left_link">
    <material>Gazebo/Black</material>
  </gazebo>
  <gazebo reference="right_link">
    <material>Gazebo/Black</material>
  </gazebo>
  <gazebo reference="lidar_link">
    <material>Gazebo/Blue</material>
    <sensor type="gpu_ray" name="head_hokuyo_sensor">
      <pose>0 0 0 0 0 0</pose>
      <visualize>false</visualize>
      <update_rate>40</update_rate>
      <ray>
        <scan>
          <horizontal>
            <samples>720</samples>
            <resolution>1</resolution>
            <min_angle>-3.14</min_angle>
            <max_angle>3.14</max_angle>
          </horizontal>
        </scan>
        <range>
          <min>0.10</min>
          <max>30.0</max>
          <resolution>0.01</resolution>
        </range>
        <noise>
          <type>gaussian</type>
          <mean>0.0</mean>
          <stddev>0.01</stddev>
        </noise>
      </ray>
      <plugin name="gazebo_ros_head_hokuyo_controller" filename="libgazebo_ros_gpu_laser.so">
        <topicName>scan</topicName>
        <frameName>lidar_link</frameName>
      </plugin>
    </sensor>
  </gazebo>
  <gazebo reference="caster_link">
    <material>Gazebo/Green</material>
  </gazebo>
  <transmission name="left_trans">
    <type>transmission_interface/SimpleTransmission</type>
    <joint name="left_joint">
      <hardwareInterface>EffortJointInterface</hardwareInterface>
    </joint>
    <actuator name="left_motor">
      <hardwareInterface>EffortJointInterface</hardwareInterface>
      <mechanicalReduction>1</mechanicalReduction>
    </actuator>
  </transmission>
  <transmission name="right_trans">
    <type>transmission_interface/SimpleTransmission</type>
    <joint name="right_joint">
      <hardwareInterface>EffortJointInterface</hardwareInterface>
    </joint>
    <actuator name="right_motor">
      <hardwareInterface>EffortJointInterface</hardwareInterface>
      <mechanicalReduction>1</mechanicalReduction>
    </actuator>
  </transmission>
  <gazebo>
    <plugin name="diff_drive" filename="libgazebo_ros_diff_drive.so">
      <!-- wheels -->
      <left_joint>left_joint</left_joint>
      <right_joint>right_joint</right_joint>

      <!-- kinematics -->
      <wheel_separation>0.21532</wheel_separation>
      <wheel_diameter>0.06985</wheel_diameter>

      <!-- limits -->
      <max_wheel_torque>5</max_wheel_torque>

      <!-- output -->
      <publish_odom>true</publish_odom>
      <publish_odom_tf>true</publish_odom_tf>
      <publish_wheel_tf>true</publish_wheel_tf>
      
      
      <odometry_frame>odom</odometry_frame>
      <robot_base_frame>base_link</robot_base_frame>
      <command_topic>cmd_vel</command_topic>
      <odometry_topic>odom</odometry_topic>
      <odometry_source>1</odometry_source>
    </plugin>
  </gazebo>
</robot>